404 error: /favicon.ico - 404 Not Found: The requested URL was not found on the server. If you entered the URL manually please check your spelling and try again.
404 error: /auth/login - 404 Not Found: The requested URL was not found on the server. If you entered the URL manually please check your spelling and try again.
404 error: /auth/login - 404 Not Found: The requested URL was not found on the server. If you entered the URL manually please check your spelling and try again.
404 error: /auth/login - 404 Not Found: The requested URL was not found on the server. If you entered the URL manually please check your spelling and try again.
2025-10-20 16:09:07,700 ERROR [app] Failed to create admin user: Could not determine join condition between parent/child tables on relationship UserSession.user - there are multiple foreign key paths linking the tables.  Specify the 'foreign_keys' argument, providing a list of those columns which should be counted as containing a foreign key reference to the parent table. [C:\Users\REKHA SRI\Desktop\dashboard2\bizvidya_dashboard\app.py:3713]
2025-10-20 16:09:07,702 ERROR [app] Data migration failed: One or more mappers failed to initialize - can't proceed with initialization of other mappers. Triggering mapper: 'Mapper[UserSession(user_sessions)]'. Original exception was: Could not determine join condition between parent/child tables on relationship UserSession.user - there are multiple foreign key paths linking the tables.  Specify the 'foreign_keys' argument, providing a list of those columns which should be counted as containing a foreign key reference to the parent table. [C:\Users\REKHA SRI\Desktop\dashboard2\bizvidya_dashboard\app.py:3728]
2025-10-20 16:09:07,702 INFO [app] Enterprise application initialized successfully [C:\Users\REKHA SRI\Desktop\dashboard2\bizvidya_dashboard\app.py:3787]
2025-10-20 16:14:27,986 ERROR [app] Failed to create admin user: Could not determine join condition between parent/child tables on relationship UserSession.user - there are multiple foreign key paths linking the tables.  Specify the 'foreign_keys' argument, providing a list of those columns which should be counted as containing a foreign key reference to the parent table. [C:\Users\REKHA SRI\Desktop\dashboard2\bizvidya_dashboard\app.py:3713]
2025-10-20 16:14:27,986 ERROR [app] Data migration failed: One or more mappers failed to initialize - can't proceed with initialization of other mappers. Triggering mapper: 'Mapper[UserSession(user_sessions)]'. Original exception was: Could not determine join condition between parent/child tables on relationship UserSession.user - there are multiple foreign key paths linking the tables.  Specify the 'foreign_keys' argument, providing a list of those columns which should be counted as containing a foreign key reference to the parent table. [C:\Users\REKHA SRI\Desktop\dashboard2\bizvidya_dashboard\app.py:3728]
2025-10-20 16:14:27,988 INFO [app] Enterprise application initialized successfully [C:\Users\REKHA SRI\Desktop\dashboard2\bizvidya_dashboard\app.py:3787]
2025-10-20 16:17:42,686 ERROR [app] Failed to create admin user: Could not determine join condition between parent/child tables on relationship Faculty.user - there are multiple foreign key paths linking the tables.  Specify the 'foreign_keys' argument, providing a list of those columns which should be counted as containing a foreign key reference to the parent table. [C:\Users\REKHA SRI\Desktop\dashboard2\bizvidya_dashboard\app.py:3714]
2025-10-20 16:17:42,688 ERROR [app] Data migration failed: One or more mappers failed to initialize - can't proceed with initialization of other mappers. Triggering mapper: 'Mapper[Faculty(faculty)]'. Original exception was: Could not determine join condition between parent/child tables on relationship Faculty.user - there are multiple foreign key paths linking the tables.  Specify the 'foreign_keys' argument, providing a list of those columns which should be counted as containing a foreign key reference to the parent table. [C:\Users\REKHA SRI\Desktop\dashboard2\bizvidya_dashboard\app.py:3729]
2025-10-20 16:17:42,689 INFO [app] Enterprise application initialized successfully [C:\Users\REKHA SRI\Desktop\dashboard2\bizvidya_dashboard\app.py:3788]
2025-10-20 17:03:56,563 ERROR [app] Failed to create admin user: Could not determine join condition between parent/child tables on relationship Faculty.user - there are multiple foreign key paths linking the tables.  Specify the 'foreign_keys' argument, providing a list of those columns which should be counted as containing a foreign key reference to the parent table. [C:\Users\REKHA SRI\Desktop\dashboard2\bizvidya_dashboard\app.py:3714]
2025-10-20 17:03:56,563 ERROR [app] Data migration failed: One or more mappers failed to initialize - can't proceed with initialization of other mappers. Triggering mapper: 'Mapper[Faculty(faculty)]'. Original exception was: Could not determine join condition between parent/child tables on relationship Faculty.user - there are multiple foreign key paths linking the tables.  Specify the 'foreign_keys' argument, providing a list of those columns which should be counted as containing a foreign key reference to the parent table. [C:\Users\REKHA SRI\Desktop\dashboard2\bizvidya_dashboard\app.py:3729]
2025-10-20 17:03:56,565 INFO [app] Enterprise application initialized successfully [C:\Users\REKHA SRI\Desktop\dashboard2\bizvidya_dashboard\app.py:3788]
2025-10-27 21:18:07,052 ERROR [appfinal] Failed to create admin user: Could not determine join condition between parent/child tables on relationship User.sessions - there are multiple foreign key paths linking the tables.  Specify the 'foreign_keys' argument, providing a list of those columns which should be counted as containing a foreign key reference to the parent table. [C:\Users\REKHA SRI\Desktop\dashboard2\bizvidya_dashboard\appfinal.py:4369]
2025-10-27 21:18:07,054 ERROR [appfinal] Data migration failed: One or more mappers failed to initialize - can't proceed with initialization of other mappers. Triggering mapper: 'Mapper[User(users)]'. Original exception was: Could not determine join condition between parent/child tables on relationship User.sessions - there are multiple foreign key paths linking the tables.  Specify the 'foreign_keys' argument, providing a list of those columns which should be counted as containing a foreign key reference to the parent table. [C:\Users\REKHA SRI\Desktop\dashboard2\bizvidya_dashboard\appfinal.py:4384]
2025-10-27 21:18:07,055 INFO [appfinal] Enterprise application initialized successfully [C:\Users\REKHA SRI\Desktop\dashboard2\bizvidya_dashboard\appfinal.py:4461]
2025-10-27 21:18:07,055 ERROR [appfinal] Application initialization failed: 'ENV' [C:\Users\REKHA SRI\Desktop\dashboard2\bizvidya_dashboard\appfinal.py:4469]
2025-10-27 23:43:39,954 ERROR [appfinal] Failed to create admin user: User.created_by and back-reference User.created_users are both of the same direction <RelationshipDirection.ONETOMANY: 1>.  Did you mean to set remote_side on the many-to-one side ? [C:\Users\REKHA SRI\Desktop\dashboard2\bizvidya_dashboard\appfinal.py:4376]
2025-10-27 23:43:39,955 ERROR [appfinal] Data migration failed: One or more mappers failed to initialize - can't proceed with initialization of other mappers. Triggering mapper: 'Mapper[User(users)]'. Original exception was: User.created_by and back-reference User.created_users are both of the same direction <RelationshipDirection.ONETOMANY: 1>.  Did you mean to set remote_side on the many-to-one side ? [C:\Users\REKHA SRI\Desktop\dashboard2\bizvidya_dashboard\appfinal.py:4391]
2025-10-27 23:43:39,956 INFO [appfinal] Enterprise application initialized successfully [C:\Users\REKHA SRI\Desktop\dashboard2\bizvidya_dashboard\appfinal.py:4468]
2025-10-27 23:43:39,956 INFO [appfinal] Application started in production mode [C:\Users\REKHA SRI\Desktop\dashboard2\bizvidya_dashboard\appfinal.py:4471]
2025-10-27 23:43:39,957 INFO [appfinal] Database: sqlite:///educational_dashboard.db [C:\Users\REKHA SRI\Desktop\dashboard2\bizvidya_dashboard\appfinal.py:4472]
2025-10-27 23:43:39,957 INFO [appfinal] CORS Origins: ['http://localhost:3000'] [C:\Users\REKHA SRI\Desktop\dashboard2\bizvidya_dashboard\appfinal.py:4473]
2025-10-27 23:43:39,958 INFO [appfinal] Starting server on port 5000 in production mode [C:\Users\REKHA SRI\Desktop\dashboard2\bizvidya_dashboard\appfinal.py:4512]
2025-10-27 23:43:56,739 ERROR [appfinal] Exception on / [GET] [C:\Users\REKHA SRI\AppData\Local\Programs\Python\Python39\lib\site-packages\flask\app.py:1414]
Traceback (most recent call last):
  File "C:\Users\REKHA SRI\AppData\Local\Programs\Python\Python39\lib\site-packages\redis\connection.py", line 264, in connect
    sock = self.retry.call_with_retry(
  File "C:\Users\REKHA SRI\AppData\Local\Programs\Python\Python39\lib\site-packages\redis\retry.py", line 46, in call_with_retry
    return do()
  File "C:\Users\REKHA SRI\AppData\Local\Programs\Python\Python39\lib\site-packages\redis\connection.py", line 265, in <lambda>
    lambda: self._connect(), lambda error: self.disconnect(error)
  File "C:\Users\REKHA SRI\AppData\Local\Programs\Python\Python39\lib\site-packages\redis\connection.py", line 627, in _connect
    raise err
  File "C:\Users\REKHA SRI\AppData\Local\Programs\Python\Python39\lib\site-packages\redis\connection.py", line 615, in _connect
    sock.connect(socket_address)
ConnectionRefusedError: [WinError 10061] No connection could be made because the target machine actively refused it

During handling of the above exception, another exception occurred:

Traceback (most recent call last):
  File "C:\Users\REKHA SRI\AppData\Local\Programs\Python\Python39\lib\site-packages\flask\app.py", line 2190, in wsgi_app
    response = self.full_dispatch_request()
  File "C:\Users\REKHA SRI\AppData\Local\Programs\Python\Python39\lib\site-packages\flask\app.py", line 1486, in full_dispatch_request
    rv = self.handle_user_exception(e)
  File "C:\Users\REKHA SRI\AppData\Local\Programs\Python\Python39\lib\site-packages\flask_cors\extension.py", line 176, in wrapped_function
    return cors_after_request(app.make_response(f(*args, **kwargs)))
  File "C:\Users\REKHA SRI\AppData\Local\Programs\Python\Python39\lib\site-packages\flask\app.py", line 1482, in full_dispatch_request
    rv = self.preprocess_request()
  File "C:\Users\REKHA SRI\AppData\Local\Programs\Python\Python39\lib\site-packages\flask\app.py", line 1974, in preprocess_request
    rv = self.ensure_sync(before_func)()
  File "C:\Users\REKHA SRI\AppData\Local\Programs\Python\Python39\lib\site-packages\flask_limiter\extension.py", line 1055, in _check_request_limit
    raise e
  File "C:\Users\REKHA SRI\AppData\Local\Programs\Python\Python39\lib\site-packages\flask_limiter\extension.py", line 1036, in _check_request_limit
    self.__evaluate_limits(endpoint, all_limits)
  File "C:\Users\REKHA SRI\AppData\Local\Programs\Python\Python39\lib\site-packages\flask_limiter\extension.py", line 978, in __evaluate_limits
    if not method(lim.limit, *args, **kwargs):
  File "C:\Users\REKHA SRI\AppData\Local\Programs\Python\Python39\lib\site-packages\limits\strategies.py", line 148, in hit
    self.storage.incr(
  File "C:\Users\REKHA SRI\AppData\Local\Programs\Python\Python39\lib\site-packages\limits\storage\base.py", line 29, in inner
    return fn(*args, **kwargs)
  File "C:\Users\REKHA SRI\AppData\Local\Programs\Python\Python39\lib\site-packages\limits\storage\redis.py", line 191, in incr
    return int(self.lua_incr_expire([key], [expiry, amount]))
  File "C:\Users\REKHA SRI\AppData\Local\Programs\Python\Python39\lib\site-packages\redis\commands\core.py", line 5931, in __call__
    return client.evalsha(self.sha, len(keys), *args)
  File "C:\Users\REKHA SRI\AppData\Local\Programs\Python\Python39\lib\site-packages\redis\commands\core.py", line 5307, in evalsha
    return self._evalsha("EVALSHA", sha, numkeys, *keys_and_args)
  File "C:\Users\REKHA SRI\AppData\Local\Programs\Python\Python39\lib\site-packages\redis\commands\core.py", line 5291, in _evalsha
    return self.execute_command(command, sha, numkeys, *keys_and_args)
  File "C:\Users\REKHA SRI\AppData\Local\Programs\Python\Python39\lib\site-packages\redis\client.py", line 533, in execute_command
    conn = self.connection or pool.get_connection(command_name, **options)
  File "C:\Users\REKHA SRI\AppData\Local\Programs\Python\Python39\lib\site-packages\redis\connection.py", line 1086, in get_connection
    connection.connect()
  File "C:\Users\REKHA SRI\AppData\Local\Programs\Python\Python39\lib\site-packages\redis\connection.py", line 270, in connect
    raise ConnectionError(self._error_message(e))
redis.exceptions.ConnectionError: Error 10061 connecting to localhost:6379. No connection could be made because the target machine actively refused it.
2025-10-27 23:43:56,825 ERROR [appfinal] Server error: 500 Internal Server Error: The server encountered an internal error and was unable to complete your request. Either the server is overloaded or there is an error in the application. [C:\Users\REKHA SRI\Desktop\dashboard2\bizvidya_dashboard\appfinal.py:4402]
2025-10-28 08:53:52,973 ERROR [appfinal] Failed to create admin user: User.created_by and back-reference User.created_users are both of the same direction <RelationshipDirection.ONETOMANY: 1>.  Did you mean to set remote_side on the many-to-one side ? [C:\Users\REKHA SRI\Desktop\dashboard2\bizvidya_dashboard\appfinal.py:4376]
2025-10-28 08:53:52,974 ERROR [appfinal] Data migration failed: One or more mappers failed to initialize - can't proceed with initialization of other mappers. Triggering mapper: 'Mapper[User(users)]'. Original exception was: User.created_by and back-reference User.created_users are both of the same direction <RelationshipDirection.ONETOMANY: 1>.  Did you mean to set remote_side on the many-to-one side ? [C:\Users\REKHA SRI\Desktop\dashboard2\bizvidya_dashboard\appfinal.py:4391]
2025-10-28 08:53:52,974 INFO [appfinal] Enterprise application initialized successfully [C:\Users\REKHA SRI\Desktop\dashboard2\bizvidya_dashboard\appfinal.py:4468]
2025-10-28 08:53:52,975 INFO [appfinal] Application started in production mode [C:\Users\REKHA SRI\Desktop\dashboard2\bizvidya_dashboard\appfinal.py:4471]
2025-10-28 08:53:52,976 INFO [appfinal] Database: sqlite:///educational_dashboard.db [C:\Users\REKHA SRI\Desktop\dashboard2\bizvidya_dashboard\appfinal.py:4472]
2025-10-28 08:53:52,977 INFO [appfinal] CORS Origins: ['http://localhost:3000'] [C:\Users\REKHA SRI\Desktop\dashboard2\bizvidya_dashboard\appfinal.py:4473]
2025-10-28 08:53:52,979 INFO [appfinal] Starting server on port 5000 in production mode [C:\Users\REKHA SRI\Desktop\dashboard2\bizvidya_dashboard\appfinal.py:4512]
2025-10-28 08:54:45,674 ERROR [appfinal] Failed to create admin user: User.created_by and back-reference User.created_users are both of the same direction <RelationshipDirection.ONETOMANY: 1>.  Did you mean to set remote_side on the many-to-one side ? [C:\Users\REKHA SRI\Desktop\dashboard2\bizvidya_dashboard\appfinal.py:4376]
2025-10-28 08:54:45,676 ERROR [appfinal] Data migration failed: One or more mappers failed to initialize - can't proceed with initialization of other mappers. Triggering mapper: 'Mapper[User(users)]'. Original exception was: User.created_by and back-reference User.created_users are both of the same direction <RelationshipDirection.ONETOMANY: 1>.  Did you mean to set remote_side on the many-to-one side ? [C:\Users\REKHA SRI\Desktop\dashboard2\bizvidya_dashboard\appfinal.py:4391]
2025-10-28 08:54:45,676 INFO [appfinal] Enterprise application initialized successfully [C:\Users\REKHA SRI\Desktop\dashboard2\bizvidya_dashboard\appfinal.py:4468]
2025-10-28 08:54:45,677 INFO [appfinal] Application started in production mode [C:\Users\REKHA SRI\Desktop\dashboard2\bizvidya_dashboard\appfinal.py:4471]
2025-10-28 08:54:45,677 INFO [appfinal] Database: sqlite:///educational_dashboard.db [C:\Users\REKHA SRI\Desktop\dashboard2\bizvidya_dashboard\appfinal.py:4472]
2025-10-28 08:54:45,678 INFO [appfinal] CORS Origins: ['http://localhost:3000'] [C:\Users\REKHA SRI\Desktop\dashboard2\bizvidya_dashboard\appfinal.py:4473]
2025-10-28 08:54:45,679 INFO [appfinal] Starting server on port 5000 in production mode [C:\Users\REKHA SRI\Desktop\dashboard2\bizvidya_dashboard\appfinal.py:4512]
2025-10-28 08:55:16,492 ERROR [appfinal] Exception on / [GET] [C:\Users\REKHA SRI\AppData\Local\Programs\Python\Python39\lib\site-packages\flask\app.py:1414]
Traceback (most recent call last):
  File "C:\Users\REKHA SRI\AppData\Local\Programs\Python\Python39\lib\site-packages\redis\connection.py", line 264, in connect
    sock = self.retry.call_with_retry(
  File "C:\Users\REKHA SRI\AppData\Local\Programs\Python\Python39\lib\site-packages\redis\retry.py", line 46, in call_with_retry
    return do()
  File "C:\Users\REKHA SRI\AppData\Local\Programs\Python\Python39\lib\site-packages\redis\connection.py", line 265, in <lambda>
    lambda: self._connect(), lambda error: self.disconnect(error)
  File "C:\Users\REKHA SRI\AppData\Local\Programs\Python\Python39\lib\site-packages\redis\connection.py", line 627, in _connect
    raise err
  File "C:\Users\REKHA SRI\AppData\Local\Programs\Python\Python39\lib\site-packages\redis\connection.py", line 615, in _connect
    sock.connect(socket_address)
ConnectionRefusedError: [WinError 10061] No connection could be made because the target machine actively refused it

During handling of the above exception, another exception occurred:

Traceback (most recent call last):
  File "C:\Users\REKHA SRI\AppData\Local\Programs\Python\Python39\lib\site-packages\flask\app.py", line 2190, in wsgi_app
    response = self.full_dispatch_request()
  File "C:\Users\REKHA SRI\AppData\Local\Programs\Python\Python39\lib\site-packages\flask\app.py", line 1486, in full_dispatch_request
    rv = self.handle_user_exception(e)
  File "C:\Users\REKHA SRI\AppData\Local\Programs\Python\Python39\lib\site-packages\flask_cors\extension.py", line 176, in wrapped_function
    return cors_after_request(app.make_response(f(*args, **kwargs)))
  File "C:\Users\REKHA SRI\AppData\Local\Programs\Python\Python39\lib\site-packages\flask\app.py", line 1482, in full_dispatch_request
    rv = self.preprocess_request()
  File "C:\Users\REKHA SRI\AppData\Local\Programs\Python\Python39\lib\site-packages\flask\app.py", line 1974, in preprocess_request
    rv = self.ensure_sync(before_func)()
  File "C:\Users\REKHA SRI\AppData\Local\Programs\Python\Python39\lib\site-packages\flask_limiter\extension.py", line 1055, in _check_request_limit
    raise e
  File "C:\Users\REKHA SRI\AppData\Local\Programs\Python\Python39\lib\site-packages\flask_limiter\extension.py", line 1036, in _check_request_limit
    self.__evaluate_limits(endpoint, all_limits)
  File "C:\Users\REKHA SRI\AppData\Local\Programs\Python\Python39\lib\site-packages\flask_limiter\extension.py", line 978, in __evaluate_limits
    if not method(lim.limit, *args, **kwargs):
  File "C:\Users\REKHA SRI\AppData\Local\Programs\Python\Python39\lib\site-packages\limits\strategies.py", line 148, in hit
    self.storage.incr(
  File "C:\Users\REKHA SRI\AppData\Local\Programs\Python\Python39\lib\site-packages\limits\storage\base.py", line 29, in inner
    return fn(*args, **kwargs)
  File "C:\Users\REKHA SRI\AppData\Local\Programs\Python\Python39\lib\site-packages\limits\storage\redis.py", line 191, in incr
    return int(self.lua_incr_expire([key], [expiry, amount]))
  File "C:\Users\REKHA SRI\AppData\Local\Programs\Python\Python39\lib\site-packages\redis\commands\core.py", line 5931, in __call__
    return client.evalsha(self.sha, len(keys), *args)
  File "C:\Users\REKHA SRI\AppData\Local\Programs\Python\Python39\lib\site-packages\redis\commands\core.py", line 5307, in evalsha
    return self._evalsha("EVALSHA", sha, numkeys, *keys_and_args)
  File "C:\Users\REKHA SRI\AppData\Local\Programs\Python\Python39\lib\site-packages\redis\commands\core.py", line 5291, in _evalsha
    return self.execute_command(command, sha, numkeys, *keys_and_args)
  File "C:\Users\REKHA SRI\AppData\Local\Programs\Python\Python39\lib\site-packages\redis\client.py", line 533, in execute_command
    conn = self.connection or pool.get_connection(command_name, **options)
  File "C:\Users\REKHA SRI\AppData\Local\Programs\Python\Python39\lib\site-packages\redis\connection.py", line 1086, in get_connection
    connection.connect()
  File "C:\Users\REKHA SRI\AppData\Local\Programs\Python\Python39\lib\site-packages\redis\connection.py", line 270, in connect
    raise ConnectionError(self._error_message(e))
redis.exceptions.ConnectionError: Error 10061 connecting to localhost:6379. No connection could be made because the target machine actively refused it.
2025-10-28 08:55:16,507 ERROR [appfinal] Server error: 500 Internal Server Error: The server encountered an internal error and was unable to complete your request. Either the server is overloaded or there is an error in the application. [C:\Users\REKHA SRI\Desktop\dashboard2\bizvidya_dashboard\appfinal.py:4402]
2025-10-28 10:05:34,785 ERROR [appfinal] Login error: One or more mappers failed to initialize - can't proceed with initialization of other mappers. Triggering mapper: 'Mapper[User(users)]'. Original exception was: User.created_by and back-reference User.created_users are both of the same direction <RelationshipDirection.ONETOMANY: 1>.  Did you mean to set remote_side on the many-to-one side ? [C:\Users\REKHA SRI\Desktop\dashboard2\bizvidya_dashboard\appfinal.py:942]
2025-10-28 10:07:24,828 ERROR [appfinal] Health check failed: One or more mappers failed to initialize - can't proceed with initialization of other mappers. Triggering mapper: 'Mapper[User(users)]'. Original exception was: User.created_by and back-reference User.created_users are both of the same direction <RelationshipDirection.ONETOMANY: 1>.  Did you mean to set remote_side on the many-to-one side ? [C:\Users\REKHA SRI\Desktop\dashboard2\bizvidya_dashboard\appfinal.py:4317]
2025-10-28 10:09:01,600 ERROR [appfinal] Health check failed: One or more mappers failed to initialize - can't proceed with initialization of other mappers. Triggering mapper: 'Mapper[User(users)]'. Original exception was: User.created_by and back-reference User.created_users are both of the same direction <RelationshipDirection.ONETOMANY: 1>.  Did you mean to set remote_side on the many-to-one side ? [C:\Users\REKHA SRI\Desktop\dashboard2\bizvidya_dashboard\appfinal.py:4317]
2025-10-28 14:14:22,589 ERROR [appfinal] Failed to create admin user: User.created_by and back-reference User.created_users are both of the same direction <RelationshipDirection.ONETOMANY: 1>.  Did you mean to set remote_side on the many-to-one side ? [C:\Users\REKHA SRI\Desktop\dashboard2\bizvidya_dashboard\appfinal.py:4376]
2025-10-28 14:14:22,592 ERROR [appfinal] Data migration failed: One or more mappers failed to initialize - can't proceed with initialization of other mappers. Triggering mapper: 'Mapper[User(users)]'. Original exception was: User.created_by and back-reference User.created_users are both of the same direction <RelationshipDirection.ONETOMANY: 1>.  Did you mean to set remote_side on the many-to-one side ? [C:\Users\REKHA SRI\Desktop\dashboard2\bizvidya_dashboard\appfinal.py:4391]
2025-10-28 14:14:22,593 INFO [appfinal] Enterprise application initialized successfully [C:\Users\REKHA SRI\Desktop\dashboard2\bizvidya_dashboard\appfinal.py:4468]
2025-10-28 14:14:22,594 INFO [appfinal] Application started in production mode [C:\Users\REKHA SRI\Desktop\dashboard2\bizvidya_dashboard\appfinal.py:4471]
2025-10-28 14:14:22,595 INFO [appfinal] Database: sqlite:///educational_dashboard.db [C:\Users\REKHA SRI\Desktop\dashboard2\bizvidya_dashboard\appfinal.py:4472]
2025-10-28 14:14:22,595 INFO [appfinal] CORS Origins: ['http://localhost:3000'] [C:\Users\REKHA SRI\Desktop\dashboard2\bizvidya_dashboard\appfinal.py:4473]
2025-10-28 14:14:22,597 INFO [appfinal] Starting server on port 5000 in production mode [C:\Users\REKHA SRI\Desktop\dashboard2\bizvidya_dashboard\appfinal.py:4512]
